Workbook

Sheet Dashboard
B1: Indian Banking Transactions Dashboard
B2: ="Data period: "&TEXT(MIN(Data!$L$2:$L$501),"dd mmm yyyy")&" to "&TEXT(MAX(Data!$L$2:$L$501),"dd mmm yyyy")&" | "&TEXT(COUNTA(Data!$A$2:$A$501),"#,##0")&" transactions in dataset" -> Data period: 11 Jul 2023 to 06 Jul 2025 | 500 transactions in dataset
B4: Filter ▸ Region | D4: All | G4: Year | I4: All | L4: Pick from the yellow drop-downs. Regional chart ignores Region; Monthly trend ignores Year.
B6: TOTAL TRANSACTIONS | F6: TOTAL VALUE (₹ CRORE) | J6: AVG TRANSACTION VALUE (₹) | N6: FRAUD RATE (FLAGGED)
B7: =COUNTIFS(Data!$E$2:$E$501,Analysis!$B$2,Data!$Q$2:$Q$501,Analysis!$B$3) -> 500 | F7: =SUMIFS(Data!$J$2:$J$501,Data!$E$2:$E$501,Analysis!$B$2,Data!$Q$2:$Q$501,Analysis!$B$3)/Analysis!$B$4 -> 9.393378 | J7: =IF(COUNTIFS(Data!$E$2:$E$501,Analysis!$B$2,Data!$Q$2:$Q$501,Analysis!$B$3)=0,0,SUMIFS(Data!$J$2:$J$501,Data!$E$2:$E$501,Analysis!$B$2,Data!$Q$2:$Q$501,Analysis!$B$3)/COUNTIFS(Data!$E$2:$E$501,Analysis!$B$2,Data!$Q$2:$Q$501,Analysis!$B$3)) -> 187867.56 | N7: =IF(COUNTIFS(Data!$E$2:$E$501,Analysis!$B$2,Data!$Q$2:$Q$501,Analysis!$B$3)=0,0,SUMIFS(Data!$S$2:$S$501,Data!$E$2:$E$501,Analysis!$B$2,Data!$Q$2:$Q$501,Analysis!$B$3)/COUNTIFS(Data!$E$2:$E$501,Analysis!$B$2,Data!$Q$2:$Q$501,Analysis!$B$3)) -> 0.026
B9: COMPLETED (% OF TXNS) | F9: PENDING (% OF TXNS) | J9: FAILED (% OF TXNS) | N9: REVERSED (% OF TXNS)
B10: =IF(COUNTIFS(Data!$E$2:$E$501,Analysis!$B$2,Data!$Q$2:$Q$501,Analysis!$B$3)=0,0,COUNTIFS(Data!$E$2:$E$501,Analysis!$B$2,Data!$Q$2:$Q$501,Analysis!$B$3,Data!$M$2:$M$501,"Completed")/COUNTIFS(Data!$E$2:$E$501,Analysis!$B$2,Data!$Q$2:$Q$501,Analysis!$B$3)) -> 0.868 | F10: =IF(COUNTIFS(Data!$E$2:$E$501,Analysis!$B$2,Data!$Q$2:$Q$501,Analysis!$B$3)=0,0,COUNTIFS(Data!$E$2:$E$501,Analysis!$B$2,Data!$Q$2:$Q$501,Analysis!$B$3,Data!$M$2:$M$501,"Pending")/COUNTIFS(Data!$E$2:$E$501,Analysis!$B$2,Data!$Q$2:$Q$501,Analysis!$B$3)) -> 0.038 | J10: =IF(COUNTIFS(Data!$E$2:$E$501,Analysis!$B$2,Data!$Q$2:$Q$501,Analysis!$B$3)=0,0,COUNTIFS(Data!$E$2:$E$501,Analysis!$B$2,Data!$Q$2:$Q$501,Analysis!$B$3,Data!$M$2:$M$501,"Failed")/COUNTIFS(Data!$E$2:$E$501,Analysis!$B$2,Data!$Q$2:$Q$501,Analysis!$B$3)) -> 0.052 | N10: =IF(COUNTIFS(Data!$E$2:$E$501,Analysis!$B$2,Data!$Q$2:$Q$501,Analysis!$B$3)=0,0,COUNTIFS(Data!$E$2:$E$501,Analysis!$B$2,Data!$Q$2:$Q$501,Analysis!$B$3,Data!$M$2:$M$501,"Reversed")/COUNTIFS(Data!$E$2:$E$501,Analysis!$B$2,Data!$Q$2:$Q$501,Analysis!$B$3)) -> 0.042
B12: DIGITAL (UPI + NET BANKING) % OF TXNS | F12: CARD-BASED % OF TXNS | J12: CASH-BASED % OF TXNS | N12: FREQUENT CUSTOMERS % OF TXNS
B13: =IF(COUNTIFS(Data!$E$2:$E$501,Analysis!$B$2,Data!$Q$2:$Q$501,Analysis!$B$3)=0,0,COUNTIFS(Data!$E$2:$E$501,Analysis!$B$2,Data!$Q$2:$Q$501,Analysis!$B$3,Data!$T$2:$T$501,"Digital")/COUNTIFS(Data!$E$2:$E$501,Analysis!$B$2,Data!$Q$2:$Q$501,Analysis!$B$3)) -> 0.348 | F13: =IF(COUNTIFS(Data!$E$2:$E$501,Analysis!$B$2,Data!$Q$2:$Q$501,Analysis!$B$3)=0,0,COUNTIFS(Data!$E$2:$E$501,Analysis!$B$2,Data!$Q$2:$Q$501,Analysis!$B$3,Data!$T$2:$T$501,"Card-Based")/COUNTIFS(Data!$E$2:$E$501,Analysis!$B$2,Data!$Q$2:$Q$501,Analysis!$B$3)) -> 0.456 | J13: =IF(COUNTIFS(Data!$E$2:$E$501,Analysis!$B$2,Data!$Q$2:$Q$501,Analysis!$B$3)=0,0,COUNTIFS(Data!$E$2:$E$501,Analysis!$B$2,Data!$Q$2:$Q$501,Analysis!$B$3,Data!$T$2:$T$501,"Cash-Based")/COUNTIFS(Data!$E$2:$E$501,Analysis!$B$2,Data!$Q$2:$Q$501,Analysis!$B$3)) -> 0.196 | N13: =IF(COUNTIFS(Data!$E$2:$E$501,Analysis!$B$2,Data!$Q$2:$Q$501,Analysis!$B$3)=0,0,COUNTIFS(Data!$E$2:$E$501,Analysis!$B$2,Data!$Q$2:$Q$501,Analysis!$B$3,Data!$U$2:$U$501,"Frequent")/COUNTIFS(Data!$E$2:$E$501,Analysis!$B$2,Data!$Q$2:$Q$501,Analysis!$B$3)) -> 0

Sheet Insights
A1: Key Insights (snapshot of the full, unfiltered dataset)
A2: These are written findings; the Dashboard tab recalculates with filters, this text does not.
A4: Theme | B4: Finding
A5: Overall | B5: 500 transactions worth ₹9.39 Cr (average ₹1.88 lakh) between Jul 2023 and 6 Jul 2025.
A6: Regions | B6: Volume is evenly spread. North leads (110 txns, ₹2.05 Cr); South is lowest (97 txns, ₹1.73 Cr).
A7: Branches | B7: Indore and Chennai are busiest (28 txns each); Mumbai is lowest (12) followed by Ranchi (14).
A8: Transaction mix | B8: Deposit 140, Online Transfer 136, Withdrawal 116, Cheque 108. Cheque and Online Transfer carry about 68% of total value (₹6.37 Cr) despite being under half of the count.
A9: Channels | B9: Debit Card is the most used mode (128 txns, 25.6%); Net Banking is the least (80, 16.0%). UPI is 94 (18.8%).
A10: Status | B10: 86.8% Completed, 5.2% Failed, 4.2% Reversed, 3.8% Pending. Failed plus Reversed value is ₹89 lakh.
A11: Fraud overall | B11: 13 flagged transactions (2.6%), worth ₹23.4 lakh; 11 of 13 were Completed, so funds actually moved.
A12: Fraud by branch | B12: Bhopal stands out: 3 of 20 transactions flagged (15%) versus 0 to 1 elsewhere. Central (4.1%) and West (4.0%) have the highest regional rates.
A13: Fraud by account / mode | B13: Savings accounts hold 7 of 13 cases (6.0% rate) against under 1% for Fixed and Recurring Deposits. Cash has the highest mode rate (5.1%); Withdrawal the highest type rate (4.3%).
A14: Transaction category | B14: Card-Based 228 txns (45.6%), Digital 174 (34.8%), Cash-Based 98 (19.6%). Cash-Based has the highest fraud rate at 5.1%, versus 2.3% for Digital and 1.8% for Card-Based.
A15: Customer type | B15: All 500 Customer IDs appear exactly once, so every customer is One-Time and none is Frequent. The Customer Type column works but cannot support loyalty analysis on this dataset.
... A17: Caution | B17: Only 13 fraud cases, so branch and segment rates are volatile. Treat them as leads for review, not proof.

Sheet Analysis
A1: Analysis Tables (feed the Dashboard charts)
A2: Region criterion | B2: =IF(Dashboard!$D$4="All","*",Dashboard!$D$4) -> * | C2: Driven by the Region / Year drop-downs on the Dashboard ('*' and '>0' mean 'All')
A3: Year criterion | B3: =IF(Dashboard!$I$4="All",">0",Dashboard!$I$4) -> >0
A4: Rupees per Crore | B4: 10000000 | C4: Assumption: 1 Crore = 10,000,000 rupees (used to show Total Value in ₹ Cr)
A6: 1. Regional volume (Year filter only)
A7: Region | B7: Txn Count | C7: Value (₹) | D7: % of Count | E7: Fraud Txns | F7: Fraud Rate
A8: Central | B8: =COUNTIFS(Data!$E$2:$E$501,$A8,Data!$Q$2:$Q$501,$B$3) -> 98 | C8: =SUMIFS(Data!$J$2:$J$501,Data!$E$2:$E$501,$A8,Data!$Q$2:$Q$501,$B$3) -> 18162309 | D8: =IF($B$13=0,0,B8/$B$13) -> 0.196 | E8: =SUMIFS(Data!$S$2:$S$501,Data!$E$2:$E$501,$A8,Data!$Q$2:$Q$501,$B$3) -> 4 | F8: =IF(B8=0,0,E8/B8) -> 0.040816327
A9: East | B9: =COUNTIFS(Data!$E$2:$E$501,$A9,Data!$Q$2:$Q$501,$B$3) -> 94 | C9: =SUMIFS(Data!$J$2:$J$501,Data!$E$2:$E$501,$A9,Data!$Q$2:$Q$501,$B$3) -> 18901843 | D9: =IF($B$13=0,0,B9/$B$13) -> 0.188 | E9: =SUMIFS(Data!$S$2:$S$501,Data!$E$2:$E$501,$A9,Data!$Q$2:$Q$501,$B$3) -> 1 | F9: =IF(B9=0,0,E9/B9) -> 0.010638298
A10: North | B10: =COUNTIFS(Data!$E$2:$E$501,$A10,Data!$Q$2:$Q$501,$B$3) -> 110 | C10: =SUMIFS(Data!$J$2:$J$501,Data!$E$2:$E$501,$A10,Data!$Q$2:$Q$501,$B$3) -> 20463124 | D10: =IF($B$13=0,0,B10/$B$13) -> 0.22 | E10: =SUMIFS(Data!$S$2:$S$501,Data!$E$2:$E$501,$A10,Data!$Q$2:$Q$501,$B$3) -> 3 | F10: =IF(B10=0,0,E10/B10) -> 0.027272727
A11: South | B11: =COUNTIFS(Data!$E$2:$E$501,$A11,Data!$Q$2:$Q$501,$B$3) -> 97 | C11: =SUMIFS(Data!$J$2:$J$501,Data!$E$2:$E$501,$A11,Data!$Q$2:$Q$501,$B$3) -> 17346670 | D11: =IF($B$13=0,0,B11/$B$13) -> 0.194 | E11: =SUMIFS(Data!$S$2:$S$501,Data!$E$2:$E$501,$A11,Data!$Q$2:$Q$501,$B$3) -> 1 | F11: =IF(B11=0,0,E11/B11) -> 0.010309278
A12: West | B12: =COUNTIFS(Data!$E$2:$E$501,$A12,Data!$Q$2:$Q$501,$B$3) -> 101 | C12: =SUMIFS(Data!$J$2:$J$501,Data!$E$2:$E$501,$A12,Data!$Q$2:$Q$501,$B$3) -> 19059835 | D12: =IF($B$13=0,0,B12/$B$13) -> 0.202 | E12: =SUMIFS(Data!$S$2:$S$501,Data!$E$2:$E$501,$A12,Data!$Q$2:$Q$501,$B$3) -> 4 | F12: =IF(B12=0,0,E12/B12) -> 0.03960396
A13: Total | B13: =SUM(B8:B12) -> 500 | C13: =SUM(C8:C12) -> 93933780 | D13: =SUM(D8:D12) -> 1 | E13: =SUM(E8:E12) -> 13 | F13: =IF(B13=0,0,E13/B13) -> 0.026
A16: 3. Channel (Payment Mode) usage
A17: Payment Mode | B17: Txn Count | C17: Value (₹) | D17: % of Count | E17: Fraud Txns | F17: Fraud Rate
A18: UPI | B18: =COUNTIFS(Data!$K$2:$K$501,$A18,Data!$E$2:$E$501,$B$2,Data!$Q$2:$Q$501,$B$3) -> 94 | C18: =SUMIFS(Data!$J$2:$J$501,Data!$K$2:$K$501,$A18,Data!$E$2:$E$501,$B$2,Data!$Q$2:$Q$501,$B$3) -> 18593361 | D18: =IF($B$23=0,0,B18/$B$23) -> 0.188 | E18: =SUMIFS(Data!$S$2:$S$501,Data!$K$2:$K$501,$A18,Data!$E$2:$E$501,$B$2,Data!$Q$2:$Q$501,$B$3) -> 2 | F18: =IF(B18=0,0,E18/B18) -> 0.021276596
A19: Debit Card | B19: =COUNTIFS(Data!$K$2:$K$501,$A19,Data!$E$2:$E$501,$B$2,Data!$Q$2:$Q$501,$B$3) -> 128 | C19: =SUMIFS(Data!$J$2:$J$501,Data!$K$2:$K$501,$A19,Data!$E$2:$E$501,$B$2,Data!$Q$2:$Q$501,$B$3) -> 23893470 | D19: =IF($B$23=0,0,B19/$B$23) -> 0.256 | E19: =SUMIFS(Data!$S$2:$S$501,Data!$K$2:$K$501,$A19,Data!$E$2:$E$501,$B$2,Data!$Q$2:$Q$501,$B$3) -> 2 | F19: =IF(B19=0,0,E19/B19) -> 0.015625
A20: Credit Card | B20: =COUNTIFS(Data!$K$2:$K$501,$A20,Data!$E$2:$E$501,$B$2,Data!$Q$2:$Q$501,$B$3) -> 100 | C20: =SUMIFS(Data!$J$2:$J$501,Data!$K$2:$K$501,$A20,Data!$E$2:$E$501,$B$2,Data!$Q$2:$Q$501,$B$3) -> 18385288 | D20: =IF($B$23=0,0,B20/$B$23) -> 0.2 | E20: =SUMIFS(Data!$S$2:$S$501,Data!$K$2:$K$501,$A20,Data!$E$2:$E$501,$B$2,Data!$Q$2:$Q$501,$B$3) -> 2 | F20: =IF(B20=0,0,E20/B20) -> 0.02
A21: Net Banking | B21: =COUNTIFS(Data!$K$2:$K$501,$A21,Data!$E$2:$E$501,$B$2,Data!$Q$2:$Q$501,$B$3) -> 80 | C21: =SUMIFS(Data!$J$2:$J$501,Data!$K$2:$K$501,$A21,Data!$E$2:$E$501,$B$2,Data!$Q$2:$Q$501,$B$3) -> 16202668 | D21: =IF($B$23=0,0,B21/$B$23) -> 0.16 | E21: =SUMIFS(Data!$S$2:$S$501,Data!$K$2:$K$501,$A21,Data!$E$2:$E$501,$B$2,Data!$Q$2:$Q$501,$B$3) -> 2 | F21: =IF(B21=0,0,E21/B21) -> 0.025
A22: Cash | B22: =COUNTIFS(Data!$K$2:$K$501,$A22,Data!$E$2:$E$501,$B$2,Data!$Q$2:$Q$501,$B$3) -> 98 | C22: =SUMIFS(Data!$J$2:$J$501,Data!$K$2:$K$501,$A22,Data!$E$2:$E$501,$B$2,Data!$Q$2:$Q$501,$B$3) -> 16858993 | D22: =IF($B$23=0,0,B22/$B$23) -> 0.196 | E22: =SUMIFS(Data!$S$2:$S$501,Data!$K$2:$K$501,$A22,Data!$E$2:$E$501,$B$2,Data!$Q$2:$Q$501,$B$3) -> 5 | F22: =IF(B22=0,0,E22/B22) -> 0.051020408
A23: Total | B23: =SUM(B18:B22) -> 500 | C23: =SUM(C18:C22) -> 93933780 | D23: =SUM(D18:D22) -> 1 | E23: =SUM(E18:E22) -> 13 | F23: =IF(B23=0,0,E23/B23) -> 0.026
A26: 4. Transaction type breakdown
A27: Transaction Type | B27: Txn Count | C27: Value (₹) | D27: % of Count | E27: Fraud Txns | F27: Fraud Rate
A28: Deposit | B28: =COUNTIFS(Data!$I$2:$I$501,$A28,Data!$E$2:$E$501,$B$2,Data!$Q$2:$Q$501,$B$3) -> 140 | C28: =SUMIFS(Data!$J$2:$J$501,Data!$I$2:$I$501,$A28,Data!$E$2:$E$501,$B$2,Data!$Q$2:$Q$501,$B$3) -> 21513155 | D28: =IF($B$32=0,0,B28/$B$32) -> 0.28 | E28: =SUMIFS(Data!$S$2:$S$501,Data!$I$2:$I$501,$A28,Data!$E$2:$E$501,$B$2,Data!$Q$2:$Q$501,$B$3) -> 1 | F28: =IF(B28=0,0,E28/B28) -> 0.0071428571
A29: Online Transfer | B29: =COUNTIFS(Data!$I$2:$I$501,$A29,Data!$E$2:$E$501,$B$2,Data!$Q$2:$Q$501,$B$3) -> 136 | C29: =SUMIFS(Data!$J$2:$J$501,Data!$I$2:$I$501,$A29,Data!$E$2:$E$501,$B$2,Data!$Q$2:$Q$501,$B$3) -> 30899200 | D29: =IF($B$32=0,0,B29/$B$32) -> 0.272 | E29: =SUMIFS(Data!$S$2:$S$501,Data!$I$2:$I$501,$A29,Data!$E$2:$E$501,$B$2,Data!$Q$2:$Q$501,$B$3) -> 5 | F29: =IF(B29=0,0,E29/B29) -> 0.036764706
A30: Withdrawal | B30: =COUNTIFS(Data!$I$2:$I$501,$A30,Data!$E$2:$E$501,$B$2,Data!$Q$2:$Q$501,$B$3) -> 116 | C30: =SUMIFS(Data!$J$2:$J$501,Data!$I$2:$I$501,$A30,Data!$E$2:$E$501,$B$2,Data!$Q$2:$Q$501,$B$3) -> 8730728.1 | D30: =IF($B$32=0,0,B30/$B$32) -> 0.232 | E30: =SUMIFS(Data!$S$2:$S$501,Data!$I$2:$I$501,$A30,Data!$E$2:$E$501,$B$2,Data!$Q$2:$Q$501,$B$3) -> 5 | F30: =IF(B30=0,0,E30/B30) -> 0.043103448
A31: Cheque | B31: =COUNTIFS(Data!$I$2:$I$501,$A31,Data!$E$2:$E$501,$B$2,Data!$Q$2:$Q$501,$B$3) -> 108 | C31: =SUMIFS(Data!$J$2:$J$501,Data!$I$2:$I$501,$A31,Data!$E$2:$E$501,$B$2,Data!$Q$2:$Q$501,$B$3) -> 32790697 | D31: =IF($B$32=0,0,B31/$B$32) -> 0.216 | E31: =SUMIFS(Data!$S$2:$S$501,Data!$I$2:$I$501,$A31,Data!$E$2:$E$501,$B$2,Data!$Q$2:$Q$501,$B$3) -> 2 | F31: =IF(B31=0,0,E31/B31) -> 0.018518519
A32: Total | B32: =SUM(B28:B31) -> 500 | C32: =SUM(C28:C31) -> 93933780 | D32: =SUM(D28:D31) -> 1 | E32: =SUM(E28:E31) -> 13 | F32: =IF(B32=0,0,E32/B32) -> 0.026
A35: 5. Transaction status
A36: Status | B36: Txn Count | C36: Value (₹) | D36: % of Count | E36: Fraud Txns | F36: Fraud Rate
A37: Completed | B37: =COUNTIFS(Data!$M$2:$M$501,$A37,Data!$E$2:$E$501,$B$2,Data!$Q$2:$Q$501,$B$3) -> 434 | C37: =SUMIFS(Data!$J$2:$J$501,Data!$M$2:$M$501,$A37,Data!$E$2:$E$501,$B$2,Data!$Q$2:$Q$501,$B$3) -> 81057860 | D37: =IF($B$41=0,0,B37/$B$41) -> 0.868 | E37: =SUMIFS(Data!$S$2:$S$501,Data!$M$2:$M$501,$A37,Data!$E$2:$E$501,$B$2,Data!$Q$2:$Q$501,$B$3) -> 11 | F37: =IF(B37=0,0,E37/B37) -> 0.025345622
A38: Pending | B38: =COUNTIFS(Data!$M$2:$M$501,$A38,Data!$E$2:$E$501,$B$2,Data!$Q$2:$Q$501,$B$3) -> 19 | C38: =SUMIFS(Data!$J$2:$J$501,Data!$M$2:$M$501,$A38,Data!$E$2:$E$501,$B$2,Data!$Q$2:$Q$501,$B$3) -> 3964708 | D38: =IF($B$41=0,0,B38/$B$41) -> 0.038 | E38: =SUMIFS(Data!$S$2:$S$501,Data!$M$2:$M$501,$A38,Data!$E$2:$E$501,$B$2,Data!$Q$2:$Q$501,$B$3) -> 0 | F38: =IF(B38=0,0,E38/B38) -> 0
A39: Failed | B39: =COUNTIFS(Data!$M$2:$M$501,$A39,Data!$E$2:$E$501,$B$2,Data!$Q$2:$Q$501,$B$3) -> 26 | C39: =SUMIFS(Data!$J$2:$J$501,Data!$M$2:$M$501,$A39,Data!$E$2:$E$501,$B$2,Data!$Q$2:$Q$501,$B$3) -> 5098603.1 | D39: =IF($B$41=0,0,B39/$B$41) -> 0.052 | E39: =SUMIFS(Data!$S$2:$S$501,Data!$M$2:$M$501,$A39,Data!$E$2:$E$501,$B$2,Data!$Q$2:$Q$501,$B$3) -> 1 | F39: =IF(B39=0,0,E39/B39) -> 0.038461538
A40: Reversed | B40: =COUNTIFS(Data!$M$2:$M$501,$A40,Data!$E$2:$E$501,$B$2,Data!$Q$2:$Q$501,$B$3) -> 21 | C40: =SUMIFS(Data!$J$2:$J$501,Data!$M$2:$M$501,$A40,Data!$E$2:$E$501,$B$2,Data!$Q$2:$Q$501,$B$3) -> 3812609 | D40: =IF($B$41=0,0,B40/$B$41) -> 0.042 | E40: =SUMIFS(Data!$S$2:$S$501,Data!$M$2:$M$501,$A40,Data!$E$2:$E$501,$B$2,Data!$Q$2:$Q$501,$B$3) -> 1 | F40: =IF(B40=0,0,E40/B40) -> 0.047619048
A41: Total | B41: =SUM(B37:B40) -> 500 | C41: =SUM(C37:C40) -> 93933780 | D41: =SUM(D37:D40) -> 1 | E41: =SUM(E37:E40) -> 13 | F41: =IF(B41=0,0,E41/B41) -> 0.026
A44: 6. Account type
A45: Account Type | B45: Txn Count | C45: Value (₹) | D45: % of Count | E45: Fraud Txns | F45: Fraud Rate
A46: Savings | B46: =COUNTIFS(Data!$H$2:$H$501,$A46,Data!$E$2:$E$501,$B$2,Data!$Q$2:$Q$501,$B$3) -> 117 | C46: =SUMIFS(Data!$J$2:$J$501,Data!$H$2:$H$501,$A46,Data!$E$2:$E$501,$B$2,Data!$Q$2:$Q$501,$B$3) -> 22732128 | D46: =IF($B$50=0,0,B46/$B$50) -> 0.234 | E46: =SUMIFS(Data!$S$2:$S$501,Data!$H$2:$H$501,$A46,Data!$E$2:$E$501,$B$2,Data!$Q$2:$Q$501,$B$3) -> 7 | F46: =IF(B46=0,0,E46/B46) -> 0.05982906
A47: Current | B47: =COUNTIFS(Data!$H$2:$H$501,$A47,Data!$E$2:$E$501,$B$2,Data!$Q$2:$Q$501,$B$3) -> 126 | C47: =SUMIFS(Data!$J$2:$J$501,Data!$H$2:$H$501,$A47,Data!$E$2:$E$501,$B$2,Data!$Q$2:$Q$501,$B$3) -> 21355142 | D47: =IF($B$50=0,0,B47/$B$50) -> 0.252 | E47: =SUMIFS(Data!$S$2:$S$501,Data!$H$2:$H$501,$A47,Data!$E$2:$E$501,$B$2,Data!$Q$2:$Q$501,$B$3) -> 4 | F47: =IF(B47=0,0,E47/B47) -> 0.031746032
A48: Fixed Deposit | B48: =COUNTIFS(Data!$H$2:$H$501,$A48,Data!$E$2:$E$501,$B$2,Data!$Q$2:$Q$501,$B$3) -> 120 | C48: =SUMIFS(Data!$J$2:$J$501,Data!$H$2:$H$501,$A48,Data!$E$2:$E$501,$B$2,Data!$Q$2:$Q$501,$B$3) -> 23006905 | D48: =IF($B$50=0,0,B48/$B$50) -> 0.24 | E48: =SUMIFS(Data!$S$2:$S$501,Data!$H$2:$H$501,$A48,Data!$E$2:$E$501,$B$2,Data!$Q$2:$Q$501,$B$3) -> 1 | F48: =IF(B48=0,0,E48/B48) -> 0.0083333333
A49: Recurring Deposit | B49: =COUNTIFS(Data!$H$2:$H$501,$A49,Data!$E$2:$E$501,$B$2,Data!$Q$2:$Q$501,$B$3) -> 137 | C49: =SUMIFS(Data!$J$2:$J$501,Data!$H$2:$H$501,$A49,Data!$E$2:$E$501,$B$2,Data!$Q$2:$Q$501,$B$3) -> 26839605 | D49: =IF($B$50=0,0,B49/$B$50) -> 0.274 | E49: =SUMIFS(Data!$S$2:$S$501,Data!$H$2:$H$501,$A49,Data!$E$2:$E$501,$B$2,Data!$Q$2:$Q$501,$B$3) -> 1 | F49: =IF(B49=0,0,E49/B49) -> 0.0072992701
...

Sheet Data
A1: Transaction ID | B1: Customer ID | C1: Customer Name | D1: Account Number | E1: Region | F1: City | G1: Branch Name | H1: Account Type | I1: Transaction Type | J1: Transaction Amount | K1: Payment Mode | L1: Transaction Date | M1: Transaction Status | N1: Balance After Txn | O1: Is Fraud | P1: year_month | Q1: Year | R1: Month Start | S1: Fraud_Flag | T1: Transaction Category | U1: Customer Type
A2: c906d56a-71d8-4309-80aa-8a668e6dd338 | B2: 989374 | C2: Indali Dhingra | D2: 748642976223 | E2: Central | F2: Indore | G2: Indore Branch | H2: Fixed Deposit | I2: Cheque | J2: 489850.94 | K2: UPI | L2: 45756 | M2: Completed | N2: 2330149 | O2: No | P2: =TEXT(L2,"yyyy-mm") -> 2025-04 | Q2: =YEAR(L2) -> 2025 | R2: =DATE(YEAR(L2),MONTH(L2),1) -> 45748 | S2: =IF(O2="Yes",1,0) -> 0 | T2: =IF(OR(K2="UPI",K2="Net Banking"),"Digital",IF(OR(K2="Debit Card",K2="Credit Card"),"Card-Based",IF(K2="Cash","Cash-Based","Unknown"))) -> Digital | U2: =IF(COUNTIF($B$2:$B$501,B2)>1,"Frequent","One-Time") -> One-Time
A3: bdbca5a9-5d6f-4b32-8e2d-c1ec810a57b1 | B3: 945035 | C3: Siya Kala | D3: 163745963749 | E3: East | F3: Guwahati | G3: Guwahati Branch | H3: Recurring Deposit | I3: Cheque | J3: 427397.73 | K3: Credit Card | L3: 45228 | M3: Completed | N3: 1668521.7 | O3: No | P3: =TEXT(L3,"yyyy-mm") -> 2023-10 | Q3: =YEAR(L3) -> 2023 | R3: =DATE(YEAR(L3),MONTH(L3),1) -> 45200 | S3: =IF(O3="Yes",1,0) -> 0 | T3: =IF(OR(K3="UPI",K3="Net Banking"),"Digital",IF(OR(K3="Debit Card",K3="Credit Card"),"Card-Based",IF(K3="Cash","Cash-Based","Unknown"))) -> Card-Based | U3: =IF(COUNTIF($B$2:$B$501,B3)>1,"Frequent","One-Time") -> One-Time
A4: 1da2b6df-97ce-4e21-8661-e764b63e2541 | B4: 934360 | C4: Tejas Rajan | D4: 193406494234 | E4: West | F4: Ahmedabad | G4: Ahmedabad Branch | H4: Fixed Deposit | I4: Withdrawal | J4: 110664.95 | K4: Net Banking | L4: 45373 | M4: Completed | N4: 853196.48 | O4: No | P4: =TEXT(L4,"yyyy-mm") -> 2024-03 | Q4: =YEAR(L4) -> 2024 | R4: =DATE(YEAR(L4),MONTH(L4),1) -> 45352 | S4: =IF(O4="Yes",1,0) -> 0 | T4: =IF(OR(K4="UPI",K4="Net Banking"),"Digital",IF(OR(K4="Debit Card",K4="Credit Card"),"Card-Based",IF(K4="Cash","Cash-Based","Unknown"))) -> Digital | U4: =IF(COUNTIF($B$2:$B$501,B4)>1,"Frequent","One-Time") -> One-Time
A5: 30ec4db1-c1da-4e6d-a17b-8ac3ed248b37 | B5: 570696 | C5: Charita Oza | D5: 170817762643 | E5: West | F5: Pune | G5: Pune Branch | H5: Recurring Deposit | I5: Cheque | J5: 121505.31 | K5: UPI | L5: 45646 | M5: Completed | N5: 926115.92 | O5: No | P5: =TEXT(L5,"yyyy-mm") -> 2024-12 | Q5: =YEAR(L5) -> 2024 | R5: =DATE(YEAR(L5),MONTH(L5),1) -> 45627 | S5: =IF(O5="Yes",1,0) -> 0 | T5: =IF(OR(K5="UPI",K5="Net Banking"),"Digital",IF(OR(K5="Debit Card",K5="Credit Card"),"Card-Based",IF(K5="Cash","Cash-Based","Unknown"))) -> Digital | U5: =IF(COUNTIF($B$2:$B$501,B5)>1,"Frequent","One-Time") -> One-Time
A6: 7e2c42ab-e97b-4765-84cc-7615869642b7 | B6: 975319 | C6: Daksh Thaman | D6: 319075165406 | E6: Central | F6: Bhopal | G6: Bhopal Branch | H6: Fixed Deposit | I6: Deposit | J6: 11528.19 | K6: Debit Card | L6: 45506 | M6: Pending | N6: 534430.58 | O6: No | P6: =TEXT(L6,"yyyy-mm") -> 2024-08 | Q6: =YEAR(L6) -> 2024 | R6: =DATE(YEAR(L6),MONTH(L6),1) -> 45505 | S6: =IF(O6="Yes",1,0) -> 0 | T6: =IF(OR(K6="UPI",K6="Net Banking"),"Digital",IF(OR(K6="Debit Card",K6="Credit Card"),"Card-Based",IF(K6="Cash","Cash-Based","Unknown"))) -> Card-Based | U6: =IF(COUNTIF($B$2:$B$501,B6)>1,"Frequent","One-Time") -> One-Time
A7: f6c20666-e23c-41bb-a870-4d16c7379d68 | B7: 895736 | C7: Zarna Mammen | D7: 253605159009 | E7: Central | F7: Bhopal | G7: Bhopal Branch | H7: Recurring Deposit | I7: Online Transfer | J7: 458663.48 | K7: Debit Card | L7: 45453 | M7: Completed | N7: 2011952.2 | O7: No | P7: =TEXT(L7,"yyyy-mm") -> 2024-06 | Q7: =YEAR(L7) -> 2024 | R7: =DATE(YEAR(L7),MONTH(L7),1) -> 45444 | S7: =IF(O7="Yes",1,0) -> 0 | T7: =IF(OR(K7="UPI",K7="Net Banking"),"Digital",IF(OR(K7="Debit Card",K7="Credit Card"),"Card-Based",IF(K7="Cash","Cash-Based","Unknown"))) -> Card-Based | U7: =IF(COUNTIF($B$2:$B$501,B7)>1,"Frequent","One-Time") -> One-Time
A8: 6c238a7e-487a-419c-895f-95878bc1a52c | B8: 390841 | C8: Ranveer Wable | D8: 945930618441 | E8: Central | F8: Raipur | G8: Raipur Branch | H8: Fixed Deposit | I8: Online Transfer | J8: 294460.92 | K8: Net Banking | L8: 45577 | M8: Completed | N8: 1713155.1 | O8: No | P8: =TEXT(L8,"yyyy-mm") -> 2024-10 | Q8: =YEAR(L8) -> 2024 | R8: =DATE(YEAR(L8),MONTH(L8),1) -> 45566 | S8: =IF(O8="Yes",1,0) -> 0 | T8: =IF(OR(K8="UPI",K8="Net Banking"),"Digital",IF(OR(K8="Debit Card",K8="Credit Card"),"Card-Based",IF(K8="Cash","Cash-Based","Unknown"))) -> Digital | U8: =IF(COUNTIF($B$2:$B$501,B8)>1,"Frequent","One-Time") -> One-Time
A9: bc35e5f4-7c5e-4606-aa23-6d21f8fdc00e | B9: 538077 | C9: Janya Oommen | D9: 960946735259 | E9: West | F9: Surat | G9: Surat Branch | H9: Recurring Deposit | I9: Cheque | J9: 70209.02 | K9: Debit Card | L9: 45436 | M9: Completed | N9: 1053966.9 | O9: No | P9: =TEXT(L9,"yyyy-mm") -> 2024-05 | Q9: =YEAR(L9) -> 2024 | R9: =DATE(YEAR(L9),MONTH(L9),1) -> 45413 | S9: =IF(O9="Yes",1,0) -> 0 | T9: =IF(OR(K9="UPI",K9="Net Banking"),"Digital",IF(OR(K9="Debit Card",K9="Credit Card"),"Card-Based",IF(K9="Cash","Cash-Based","Unknown"))) -> Card-Based | U9: =IF(COUNTIF($B$2:$B$501,B9)>1,"Frequent","One-Time") -> One-Time
A10: e6d3886e-aca3-43c0-bf91-e8d20f87eca1 | B10: 536413 | C10: Pranav Sarraf | D10: 920065850736 | E10: North | F10: Amritsar | G10: Amritsar Branch | H10: Current | I10: Cheque | J10: 305297.37 | K10: Credit Card | L10: 45531 | M10: Completed | N10: 2242547.9 | O10: No | P10: =TEXT(L10,"yyyy-mm") -> 2024-08 | Q10: =YEAR(L10) -> 2024 | R10: =DATE(YEAR(L10),MONTH(L10),1) -> 45505 | S10: =IF(O10="Yes",1,0) -> 0 | T10: =IF(OR(K10="UPI",K10="Net Banking"),"Digital",IF(OR(K10="Debit Card",K10="Credit Card"),"Card-Based",IF(K10="Cash","Cash-Based","Unknown"))) -> Card-Based | U10: =IF(COUNTIF($B$2:$B$501,B10)>1,"Frequent","One-Time") -> One-Time
A11: e3a56d54-c6b9-40fb-affd-049c92df79ce | B11: 706008 | C11: Arunima Andra | D11: 246399826650 | E11: Central | F11: Raipur | G11: Raipur Branch | H11: Savings | I11: Deposit | J11: 79976.37 | K11: Credit Card | L11: 45273 | M11: Completed | N11: 1766313.5 | O11: No | P11: =TEXT(L11,"yyyy-mm") -> 2023-12 | Q11: =YEAR(L11) -> 2023 | R11: =DATE(YEAR(L11),MONTH(L11),1) -> 45261 | S11: =IF(O11="Yes",1,0) -> 0 | T11: =IF(OR(K11="UPI",K11="Net Banking"),"Digital",IF(OR(K11="Debit Card",K11="Credit Card"),"Card-Based",IF(K11="Cash","Cash-Based","Unknown"))) -> Card-Based | U11: =IF(COUNTIF($B$2:$B$501,B11)>1,"Frequent","One-Time") -> One-Time
A12: f6d81624-e6e6-42d1-8653-88f03bbfb88b | B12: 615941 | C12: Anusha Parmar | D12: 269059820502 | E12: West | F12: Nagpur | G12: Nagpur Branch | H12: Current | I12: Cheque | J12: 426427.56 | K12: Debit Card | L12: 45121 | M12: Completed | N12: 836675.46 | O12: No | P12: =TEXT(L12,"yyyy-mm") -> 2023-07 | Q12: =YEAR(L12) -> 2023 | R12: =DATE(YEAR(L12),MONTH(L12),1) -> 45108 | S12: =IF(O12="Yes",1,0) -> 0 | T12: =IF(OR(K12="UPI",K12="Net Banking"),"Digital",IF(OR(K12="Debit Card",K12="Credit Card"),"Card-Based",IF(K12="Cash","Cash-Based","Unknown"))) -> Card-Based | U12: =IF(COUNTIF($B$2:$B$501,B12)>1,"Frequent","One-Time") -> One-Time
A13: ab65a169-4325-491e-9d38-48ef43acc5e5 | B13: 565614 | C13: Utkarsh Narain | D13: 682739590821 | E13: West | F13: Ahmedabad | G13: Ahmedabad Branch | H13: Fixed Deposit | I13: Cheque | J13: 484637.66 | K13: Net Banking | L13: 45485 | M13: Pending | N13: 1552234 | O13: No | P13: =TEXT(L13,"yyyy-mm") -> 2024-07 | Q13: =YEAR(L13) -> 2024 | R13: =DATE(YEAR(L13),MONTH(L13),1) -> 45474 | S13: =IF(O13="Yes",1,0) -> 0 | T13: =IF(OR(K13="UPI",K13="Net Banking"),"Digital",IF(OR(K13="Debit Card",K13="Credit Card"),"Card-Based",IF(K13="Cash","Cash-Based","Unknown"))) -> Digital | U13: =IF(COUNTIF($B$2:$B$501,B13)>1,"Frequent","One-Time") -> One-Time
... A501: d693559f-22c7-4d70-b7d7-1a57dc0eca8e | B501: 429704 | C501: Tristan Brar | D501: 127631697094 | E501: Central | F501: Gwalior | G501: Gwalior Branch | H501: Current | I501: Deposit | J501: 140084.77 | K501: Net Banking | L501: 45842 | M501: Completed | N501: 1217164.4 | O501: No | P501: =TEXT(L501,"yyyy-mm") -> 2025-07 | Q501: =YEAR(L501) -> 2025 | R501: =DATE(YEAR(L501),MONTH(L501),1) -> 45839 | S501: =IF(O501="Yes",1,0) -> 0 | T501: =IF(OR(K501="UPI",K501="Net Banking"),"Digital",IF(OR(K501="Debit Card",K501="Credit Card"),"Card-Based",IF(K501="Cash","Cash-Based","Unknown"))) -> Digital | U501: =IF(COUNTIF($B$2:$B$501,B501)>1,"Frequent","One-Time") -> One-Time

Sheet Fraud Cases
A1: Fraud-flagged transactions (Is Fraud = Yes), sorted by amount
A2: Static extract of the Data sheet (equivalent to filtering Is Fraud = Yes). Re-filter the Data sheet if the source data changes.
A4: Transaction ID | B4: Customer Name | C4: Account Number | D4: Region | E4: Branch Name | F4: Account Type | G4: Transaction Type | H4: Payment Mode | I4: Transaction Amount | J4: Transaction Date | K4: Transaction Status
A5: b3834752-78e5-4a8d-80a4-5004976b843d | B5: Yashvi Tiwari | C5: 775725282488 | D5: Central | E5: Bhopal Branch | F5: Savings | G5: Online Transfer | H5: Credit Card | I5: 477061.46 | J5: 45450 | K5: Completed
A6: 20712dae-f3a4-40e9-a123-c5ee6b9c4ac0 | B6: Gaurangi Chaudhry | C6: 985206008802 | D6: West | E6: Pune Branch | F6: Current | G6: Cheque | H6: Cash | I6: 460250.13 | J6: 45371 | K6: Completed
A7: 4b20ef1f-2692-43bf-ada8-d664d089f7fb | B7: Daksh Deep | C7: 963159668295 | D7: South | E7: Hyderabad Branch | F7: Current | G7: Deposit | H7: Cash | I7: 263052.93 | J7: 45367 | K7: Reversed
A8: c029cdf7-f81a-4da7-a31e-668415613c29 | B8: Brinda Minhas | C8: 858729220350 | D8: Central | E8: Bhopal Branch | F8: Recurring Deposit | G8: Cheque | H8: Net Banking | I8: 238817.39 | J8: 45580 | K8: Completed
A9: 91b14ab8-1c7a-449b-9db4-478f54442982 | B9: Jack Sridhar | C9: 590927660148 | D9: North | E9: Delhi Branch | F9: Fixed Deposit | G9: Online Transfer | H9: Credit Card | I9: 228752.03 | J9: 45348 | K9: Completed
A10: f0854809-469d-4aa2-8877-57ce3be1ae32 | B10: Owen Bedi | C10: 653060642611 | D10: West | E10: Ahmedabad Branch | F10: Savings | G10: Online Transfer | H10: Cash | I10: 151050.63 | J10: 45380 | K10: Failed
A11: 1fd55cf2-fd94-4d94-9af8-3edfb4331750 | B11: Leena Sheth | C11: 594804478063 | D11: North | E11: Chandigarh Branch | F11: Savings | G11: Online Transfer | H11: UPI | I11: 118445.89 | J11: 45791 | K11: Completed
A12: 7c0b8276-4c0c-4323-a876-980051a56c15 | B12: Isaac Peri | C12: 693909368952 | D12: West | E12: Nagpur Branch | F12: Current | G12: Withdrawal | H12: Debit Card | I12: 113984.02 | J12: 45567 | K12: Completed
A13: df7f7ea9-393c-4be3-a7da-184827e7c971 | B13: Patrick Oommen | C13: 128421661114 | D13: West | E13: Surat Branch | F13: Savings | G13: Withdrawal | H13: Cash | I13: 94310.27 | J13: 45623 | K13: Completed
A14: c9d0af20-d50b-46a5-b8b1-9f5a32fa9092 | B14: Umang Dutt | C14: 134008821990 | D14: Central | E14: Bhopal Branch | F14: Savings | G14: Withdrawal | H14: Net Banking | I14: 85345.93 | J14: 45443 | K14: Completed
A15: 815e14eb-2098-46d6-bb0d-3339ed33578a | B15: Hredhaan Aurora | C15: 575318543797 | D15: North | E15: Jaipur Branch | F15: Savings | G15: Withdrawal | H15: Debit Card | I15: 79178.86 | J15: 45797 | K15: Completed
A16: c6b86e5e-fd8f-43fc-b48e-afc11df5a541 | B16: Kamala Dhaliwal | C16: 593004841860 | D16: Central | E16: Raipur Branch | F16: Savings | G16: Withdrawal | H16: UPI | I16: 17312.52 | J16: 45798 | K16: Completed
A17: d35f18d6-9da9-4d7f-ac7e-5ec8d4a166b0 | B17: Yash Dayal | C17: 847891210164 | D17: East | E17: Patna Branch | F17: Current | G17: Online Transfer | H17: Cash | I17: 15732.38 | J17: 45366 | K17: Completed
A18: Total flagged | B18: =COUNTA(A5:A17) -> 13 | H18: Total value (₹) | I18: =SUM(I5:I17) -> 2343294.4

Sheet Cleaning Log
A1: Step 2 – Data Cleaning & Validation Log
A2: Results are live formulas against the Data sheet. PASS = no action needed.
A4: Check | B4: Result | C4: Expected | D4: Status | E4: Action / Note
A5: Rows in dataset | B5: =COUNTA(Data!$A$2:$A$501) -> 500 | D5: Informational | E5: 500 transactions loaded.
A6: Duplicate Transaction IDs | B6: =SUMPRODUCT((COUNTIF(Data!$A$2:$A$501,Data!$A$2:$A$501)>1)*1) -> 0 | C6: 0 | D6: =IF(B6=C6,"PASS","REVIEW") -> PASS | E6: No duplicates found, so no rows removed.
A7: Blank cells in source columns A:O | B7: =COUNTBLANK(Data!$A$2:$O$501) -> 0 | C7: 0 | D7: =IF(B7=C7,"PASS","REVIEW") -> PASS | E7: No missing amounts, statuses or flags; nothing to impute.
A8: Transaction Amount ≤ 0 | B8: =COUNTIF(Data!$J$2:$J$501,"<=0") -> 0 | C8: 0 | D8: =IF(B8=C8,"PASS","REVIEW") -> PASS | E8: All amounts positive.
A9: Status values outside Completed/Failed/Reversed/Pending | B9: =ROWS(Data!$M$2:$M$501)-SUMPRODUCT(COUNTIF(Data!$M$2:$M$501,{"Completed","Failed","Reversed","Pending"})) -> 0 | C9: 0 | D9: =IF(B9=C9,"PASS","REVIEW") -> PASS | E9: No unknown statuses.
A10: Is Fraud values outside Yes/No | B10: =ROWS(Data!$O$2:$O$501)-SUMPRODUCT(COUNTIF(Data!$O$2:$O$501,{"Yes","No"})) -> 0 | C10: 0 | D10: =IF(B10=C10,"PASS","REVIEW") -> PASS | E10: Flag column is clean.
A11: Region names with inconsistent case/spacing | B11: =SUMPRODUCT(--NOT(EXACT(Data!$E$2:$E$501,PROPER(TRIM(Data!$E$2:$E$501))))) -> 0 | C11: 0 | D11: =IF(B11=C11,"PASS","REVIEW") -> PASS | E11: Names already standardised.
A12: City names with inconsistent case/spacing | B12: =SUMPRODUCT(--NOT(EXACT(Data!$F$2:$F$501,PROPER(TRIM(Data!$F$2:$F$501))))) -> 0 | C12: 0 | D12: =IF(B12=C12,"PASS","REVIEW") -> PASS | E12: Names already standardised.
A13: Branch names with inconsistent case/spacing | B13: =SUMPRODUCT(--NOT(EXACT(Data!$G$2:$G$501,PROPER(TRIM(Data!$G$2:$G$501))))) -> 0 | C13: 0 | D13: =IF(B13=C13,"PASS","REVIEW") -> PASS | E13: No 'DELHI' vs 'Delhi' style variants; names were trimmed anyway.
A14: Branch Name ≠ City + ' Branch' | B14: =SUMPRODUCT(--(Data!$G$2:$G$501<>Data!$F$2:$F$501&" Branch")) -> 0 | C14: 0 | D14: =IF(B14=C14,"PASS","REVIEW") -> PASS | E14: Branch and City always agree (25 branches).
A15: year_month blank in source file | B15: 500 | D15: Fixed | E15: Column was empty in the upload. Rebuilt as =TEXT(date,"yyyy-mm") (Data!P).
A16: Account Number stored as number | B16: 500 | D16: Fixed | E16: Converted to text so 12-digit IDs never show as 7.48643E+11 in Excel.
A17: Fraud_Flag disagrees with Is Fraud | B17: =SUMPRODUCT(--((Data!$O$2:$O$501="Yes")<>(Data!$S$2:$S$501=1))) -> 0 | C17: 0 | D17: =IF(B17=C17,"PASS","REVIEW") -> PASS | E17: Fraud_Flag (1/0) is derived from Is Fraud, so they must always agree.
A18: Transaction Category = Unknown | B18: =COUNTIF(Data!$T$2:$T$501,"Unknown") -> 0 | C18: 0 | D18: =IF(B18=C18,"PASS","REVIEW") -> PASS | E18: Every Payment Mode maps to Digital, Card-Based or Cash-Based.
A19: Customer Type = Frequent | B19: =COUNTIF(Data!$U$2:$U$501,"Frequent") -> 0 | D19: Informational | E19: Every Customer ID appears once, so all customers are One-Time. The column works but cannot segment this dataset.
A20: Derived columns added | B20: 5 | D20: Added | E20: Year, Month Start, Fraud_Flag, Transaction Category, Customer Type (Data!Q:U), all formulas.
A22: Blue = hardcoded value recorded from inspecting the original upload (not recomputable once fixed).
A23: Observation (not changed): Transaction Type and Payment Mode appear independent (e.g. 'Online Transfer' paid by Cash, 'Cheque' paid by UPI). Likely synthetic data; kept as-is.

Sheet Data Understanding
A1: Step 1 – Data Understanding
A3: Column | B3: Data Type | C3: Field Class | D3: Business Relevance
A4: Transaction ID | B4: Text (UUID) | C4: Transactional | D4: Unique key; used for de-duplication
A5: Customer ID | B5: Integer | C5: Customer-level | D5: Links activity to a customer
A6: Customer Name | B6: Text | C6: Customer-level | D6: Account holder (personal data; restrict sharing)
A7: Account Number | B7: Text (12 digits) | C7: Customer-level | D7: Account identifier; must be stored as text
A8: Region | B8: Categorical | C8: Customer-level | D8: North / South / East / West / Central roll-up
A9: City | B9: Categorical | C9: Customer-level | D9: City of the branch
A10: Branch Name | B10: Categorical | C10: Customer-level | D10: '<City> Branch'; unit for volume and fraud ranking
A11: Account Type | B11: Categorical | C11: Customer-level | D11: Savings / Current / Fixed Deposit / Recurring Deposit
A12: Transaction Type | B12: Categorical | C12: Transactional | D12: Deposit / Withdrawal / Online Transfer / Cheque
A13: Transaction Amount | B13: Decimal (₹) | C13: Transactional | D13: Transaction value; main volume measure
A14: Payment Mode | B14: Categorical | C14: Transactional | D14: Used as the CHANNEL field: UPI, Debit Card, Credit Card, Net Banking, Cash
... A24: Customer Type | B24: Categorical | C24: Derived | D24: Frequent if the Customer ID has more than 1 transaction, else One-Time
A26: Differences from the case-study field list
A27: • No separate 'Channel' column: Payment Mode (UPI, Debit/Credit Card, Net Banking, Cash) is used as the channel. ATM, Branch and Mobile App channels are not in this data.
A28: • Transaction Type has Deposit, Withdrawal, Online Transfer and Cheque (there is no plain 'Transfer'). Online Transfer is treated as the transfer category.
A29: • Region has 5 values (no North-East); Guwahati is mapped to East. Branch Name is '<City> Branch' (25 branches), not 'Delhi CP'-style names.
A30: • Account Type has Savings, Current, Fixed Deposit and Recurring Deposit.
